<section class="project-container">
    <div class="project-container__logo">
        <img src="" alt="Logo" srcset="">
    </div>
    
    <p class="project-name">Урок 18. Работа с исключениями</p>
    <div class="description-block">
	    <article class="description-block__text">
          <p>В некоторых ситуациях мы знаем, что при выполнении кода могут возникнуть ошибки. Если эти исключения не обработать, то ваше приложение может “сломаться” -- то есть выдать критическую ошибку и закрыться. В таких участках мы используем конструкцию try/except/finally</p>
          <p>Предположим, мы ожидаем, что в нашу (гипотетическую) программу, которая делит число 10 на переданное число, могут передать любую цифру, в том числе 0. При делении на ноль, Python выдает следующее исключение (exception):</p>
          <p>passed_number = 0</p>
          <p>our_magic_number = 42</p>
          <p>result = our_magic_number / passed_number</p>
          <p>Traceback (most recent call last):</p>
          <p>  File "<stdin>", line 1, in <module></p>
          <p>ZeroDivisionError: division by zero</p>
          <p>Когда такого рода ошибки происходят, программа, как уже говорилось, ломается. Мы “ловим” исключения таким образом:</p>
          <p>passed_number = 0</p>
          <p>our_magic_number = 42</p>
          <p>result = None</p>
          <p>try:</p>
          <p>...&emsp;     result = our_magic_number / passed_number</p>
          <p>... except ZeroDivisionError:</p>
          <p>...&emsp;     result = 0</p>
          <p>... finally:</p>
          <p>...&emsp;     print('Calculation is done')</p>
          <p>... </p>
          <p>Calculation is done</p>
          <p>>>></p>
          <p>Что здесь произошло? Мы прикинулись, что passed_number содержит число, которое передал пользователь (для упрощения примера). our_magic_number - число, которое “прошитое” в коде (прикинемся, что это очень важное число, которое помогает нам вычислить какие-то важные вещи). Конструкцию открывает ключевое слово try, далее идет двоеточие, которое традиционно открывает блок кода с отступом в четыре пробела. В данном блоке находится код, где потенциально может произойти “авария”, и внизу, после блока try идёт except, где мы указываем тип исключения, на который должен реагировать следующий блок. В нашем случае, мы реагируем на тип исключения “ZeroDivisionError”, и в качестве реакции в переменную result записываем 0, так как в теле try при попытке записать результат вычисления произошла ошибка, и в переменной result все еще хранится None (чего мы не хотим).</p>
          <p>А код в блоке finally выполняется при любом исходе. В этом смысл этого блока -- выполнять код при любом исходе try/except.</p>
          <p>Важно понимать, что при обработке исключения в блоке except также может быть выдано исключение, для обработки которой может быть добавлен еще один блок exception.</p>
          <p><b>Задание:</b></p>
          <p>1. Напишите функцию, которая берет два аргумента (x и y) и делит их друг на друга. То есть, делит x на y. Оберните тело функции конструкцией try/except, чтобы в случае возникновения арифметических ошибок, таких как деление на ноль, выдавался результат 0.</p>
          <p>2. Напишите функцию, которая берет два аргумента (x и y) и складывает их друг с другом. Оберните тело функции конструкцией try/except, чтобы не возникало ошибки в сл</p>
      </article>
        <div class="description-block__image">
            <img src="" alt="" srcset="">
        </div>
    </div>
</section>